Workbook

Sheet GPQ Scores
A1: IGN | B1: User 1 | C1: USer 2
A2: Class | B2: Dual Blade | C2: Night Lord
A3: Last Week Score | B3: =IFERROR(__xludf.DUMMYFUNCTION("INDEX(FILTER(B12:B906,B12:B906<>""""), COUNTA(FILTER(B12:B906,B12:B906<>""""))-1)"),38970.0) -> 38970 | C3: =IFERROR(__xludf.DUMMYFUNCTION("INDEX(FILTER(C12:C906,C12:C906<>""""), COUNTA(FILTER(C12:C906,C12:C906<>""""))-1)"),22935.0) -> 22935
A4: Current Week Score | B4: =IFERROR(__xludf.DUMMYFUNCTION("INDEX(FILTER(B12:B906,B12:B906<>""""), COUNTA(FILTER(B12:B906,B12:B906<>"""")))"),40721.0) -> 40721 | C4: =IFERROR(__xludf.DUMMYFUNCTION("INDEX(FILTER(C12:C906,C12:C906<>""""), COUNTA(FILTER(C12:C906,C12:C906<>"""")))"),23128.0) -> 23128
A5: Change compared to last week | B5: =(B4-B3)/B3 -> 0.044931999 | C5: =(C4-C3)/C3 -> 0.0084150861
A6: GPQ Weekly Rank | B6: =rank(B4,$B$4:$AKY$4,0) -> 1 | C6: =rank(C4,$B$4:$AKY$4,0) -> 2
A7: Personal Best | B7: =max(B12:B906) -> 40721 | C7: =max(C12:C906) -> 23128
A8: Current vs. Best | B8: =(B4-B7)/B7 -> 0 | C8: =(C4-C7)/C7 -> 0
A9: Active Weeks | B9: =count(B12:B906) -> 35 | C9: =count(C12:C906) -> 43
A10: Participation Rate | B10: =(1-(countif(B12:B906,0))/(count(B12:B906))) -> 0.94285714 | C10: =(1-(countif(C12:C906,0))/(count(C12:C906))) -> 0.95348837
A11: Date (MM/DD/YY)
A12: 45207 | C12: 6123
A13: =A12+7 -> 45214 | C13: 6118
A14: =A13+7 -> 45221 | C14: 6442
A15: =A14+7 -> 45228 | C15: 8820
A16: =A15+7 -> 45235 | C16: 9530
A17: =A16+7 -> 45242 | C17: 10165
A18: =A17+7 -> 45249 | C18: 9919
A19: =A18+7 -> 45256 | C19: 11535
A20: =A19+7 -> 45263 | B20: 20406 | C20: 11307
A21: =A20+7 -> 45270 | B21: 20758 | C21: 12736
A22: =A21+7 -> 45277 | B22: 22460 | C22: 12568
A23: =A22+7 -> 45284 | B23: 23154 | C23: 11830
A24: =A23+7 -> 45291 | B24: 24427 | C24: 14201
A25: =A24+7 -> 45298 | B25: 25111 | C25: 15417
A26: =A25+7 -> 45305 | B26: 23742 | C26: 16173
A27: =A26+7 -> 45312 | B27: 24524 | C27: 15798
A28: =A27+7 -> 45319 | B28: 26131 | C28: 13861
A29: =A28+7 -> 45326 | B29: 26283 | C29: 16453
A30: =A29+7 -> 45333 | B30: 25904 | C30: 13970
A31: =A30+7 -> 45340 | B31: 24262 | C31: 15111
... A43: =A42+7 -> 45424 | B43: 33967 | C43: 18636
A44: 45431 | B44: 0 | C44: 0
A45: 45438 | B45: 0 | C45: 0
A46: 45445 | B46: 35400 | C46: 17160
A47: 45452 | B47: 28731 | C47: 17989
A48: 45459 | B48: 33638 | C48: 18668
A49: 45466 | B49: 30962 | C49: 20002
A50: 45473 | B50: 36892 | C50: 18539
A51: 45480 | B51: 34777 | C51: 18174
...

Sheet Guild Scores!
A1: Date | B1: GPQ | C1: Rank | D1: Number of People running | E1: Average Member Score
A2: 45207 | B2: =sum('GPQ Scores'!C12:AKX12) -> 6123 | D2: =COUNTIF('GPQ Scores'!C12:AJE12,">1") -> 1 | E2: =B2/D2 -> 6123
A3: =A2+7 -> 45214 | B3: =sum('GPQ Scores'!C13:AKX13) -> 6118 | D3: =COUNTIF('GPQ Scores'!C13:AJE13,">1") -> 1 | E3: =B3/D3 -> 6118
A4: =A3+7 -> 45221 | B4: =sum('GPQ Scores'!C14:AKP14) -> 6442 | D4: =COUNTIF('GPQ Scores'!C14:AJE14,">1") -> 1 | E4: =B4/D4 -> 6442
A5: =A4+7 -> 45228 | B5: =sum('GPQ Scores'!C15:AKP15) -> 8820 | D5: =COUNTIF('GPQ Scores'!C15:AJE15,">1") -> 1 | E5: =B5/D5 -> 8820
A6: =A5+7 -> 45235 | B6: =sum('GPQ Scores'!C16:AKP16) -> 9530 | C6: 252 | D6: =COUNTIF('GPQ Scores'!C16:AJE16,">1") -> 1 | E6: =B6/D6 -> 9530
A7: =A6+7 -> 45242 | B7: =sum('GPQ Scores'!C17:AKP17) -> 10165 | C7: 238 | D7: =COUNTIF('GPQ Scores'!C17:AJE17,">1") -> 1 | E7: =B7/D7 -> 10165
A8: =A7+7 -> 45249 | B8: =sum('GPQ Scores'!C18:AID18) -> 9919 | C8: 223 | D8: =COUNTIF('GPQ Scores'!C18:AJE18,">1") -> 1 | E8: =B8/D8 -> 9919
A9: =A8+7 -> 45256 | B9: =sum('GPQ Scores'!C19:AKP19) -> 11535 | C9: 201 | D9: =COUNTIF('GPQ Scores'!B19:AJE19,">1") -> 1 | E9: =B9/D9 -> 11535
A10: =A9+7 -> 45263 | B10: =sum('GPQ Scores'!B20:AKP20) -> 31713 | C10: 180 | D10: =COUNTIF('GPQ Scores'!B20:AJE20,">1") -> 2 | E10: =B10/D10 -> 15856.5
A11: =A10+7 -> 45270 | B11: =sum('GPQ Scores'!B21:AKP21) -> 33494 | C11: 169 | D11: =COUNTIF('GPQ Scores'!C21:AJE21,">1") -> 1 | E11: =B11/D11 -> 33494
A12: =A11+7 -> 45277 | B12: =sum('GPQ Scores'!B22:AKP22) -> 35028 | C12: 164 | D12: =COUNTIF('GPQ Scores'!C22:AJE22,">1") -> 1 | E12: =B12/D12 -> 35028
A13: =A12+7 -> 45284 | B13: =sum('GPQ Scores'!B23:AKP23) -> 34984 | C13: 159 | D13: =COUNTIF('GPQ Scores'!C23:AJE23,">1") -> 1 | E13: =B13/D13 -> 34984
A14: =A13+7 -> 45291 | B14: =sum('GPQ Scores'!B24:AKP24) -> 38628 | C14: 168 | D14: =COUNTIF('GPQ Scores'!C24:AJE24,">1") -> 1 | E14: =B14/D14 -> 38628
A15: =A14+7 -> 45298 | B15: =sum('GPQ Scores'!B25:AKP25) -> 40528 | C15: 167 | D15: =COUNTIF('GPQ Scores'!C25:AJE25,">1") -> 1 | E15: =B15/D15 -> 40528
A16: =A15+7 -> 45305 | B16: =sum('GPQ Scores'!B26:AKP26) -> 39915 | C16: 150 | D16: =COUNTIF('GPQ Scores'!C26:AJE26,">1") -> 1 | E16: =B16/D16 -> 39915
A17: =A16+7 -> 45312 | B17: =sum('GPQ Scores'!B27:AKP27) -> 40322 | C17: 158 | D17: =COUNTIF('GPQ Scores'!C27:AJE27,">1") -> 1 | E17: =B17/D17 -> 40322
A18: =A17+7 -> 45319 | B18: =sum('GPQ Scores'!B28:AKP28) -> 39992 | C18: 159 | D18: =COUNTIF('GPQ Scores'!C28:AJE28,">1") -> 1 | E18: =B18/D18 -> 39992
A19: =A18+7 -> 45326 | B19: =sum('GPQ Scores'!B29:AKP29) -> 42736 | C19: 153 | D19: =COUNTIF('GPQ Scores'!C29:AJE29,">1") -> 1 | E19: =B19/D19 -> 42736
A20: =A19+7 -> 45333 | B20: =sum('GPQ Scores'!B30:AKP30) -> 39874 | C20: 160 | D20: =COUNTIF('GPQ Scores'!C30:AJE30,">1") -> 1 | E20: =B20/D20 -> 39874
A21: =A20+7 -> 45340 | B21: =sum('GPQ Scores'!B31:AKP31) -> 39373 | C21: 157 | D21: =COUNTIF('GPQ Scores'!C31:AJE31,">1") -> 1 | E21: =B21/D21 -> 39373
A22: =A21+7 -> 45347 | B22: =sum('GPQ Scores'!B32:AKP32) -> 38100 | C22: 223 | D22: =COUNTIF('GPQ Scores'!C32:AJE32,">1") -> 1 | E22: =B22/D22 -> 38100
... A32: =A31+7 -> 45417 | B32: =sum('GPQ Scores'!B42:AKP42) -> 50493 | C32: 136 | D32: =COUNTIF('GPQ Scores'!C42:AJE42,">1") -> 1 | E32: =B32/D32 -> 50493
A33: =A32+7 -> 45424 | B33: {=SUM('GPQ Scores'!B43:JX43)} -> 52603 | D33: {=COUNTIF('GPQ Scores'!B43:JX43, ">1")} -> 2 | E33: {=AVERAGEIF('GPQ Scores'!B43:JX43, "<>0")} -> 26301.5
A34: =A33+7 -> 45431 | B34: {=SUM('GPQ Scores'!B44:JX44)} -> 0 | D34: =COUNTIF('GPQ Scores'!C44:AJE44,">1") -> 0 | E34: =B34/D34 -> #DIV/0!
A35: =A34+7 -> 45438 | B35: {=SUM('GPQ Scores'!B45:JX45)} -> 0 | D35: {=COUNTIF('GPQ Scores'!B45:JX45, ">1")} -> 0 | E35: {=AVERAGEIF('GPQ Scores'!B45:JX45, "<>0")} -> #DIV/0!
A36: =A35+7 -> 45445 | B36: {=SUM('GPQ Scores'!B46:ACQ46)} -> 52560 | C36: 101 | D36: {=COUNTIF('GPQ Scores'!B46:JX46, ">1")} -> 2 | E36: {=AVERAGEIF('GPQ Scores'!B46:JX46, "<>0")} -> 26280
A37: =A36+7 -> 45452 | B37: {=SUM('GPQ Scores'!B47:ACQ47)} -> 46720 | C37: 116 | D37: {=COUNTIF('GPQ Scores'!B47:JX47, ">1")} -> 2 | E37: {=AVERAGEIF('GPQ Scores'!B47:JX47, "<>0")} -> 23360
A38: =A37+7 -> 45459 | B38: {=SUM('GPQ Scores'!B48:ACQ48)} -> 52306 | C38: 106 | D38: {=COUNTIF('GPQ Scores'!B48:JX48, ">1")} -> 2 | E38: {=AVERAGEIF('GPQ Scores'!B48:JX48, "<>0")} -> 26153
A39: =A38+7 -> 45466 | B39: {=SUM('GPQ Scores'!B49:ACQ49)} -> 50964 | D39: {=COUNTIF('GPQ Scores'!B49:JX49, ">1")} -> 2 | E39: {=AVERAGEIF('GPQ Scores'!B49:JX49, "<>0")} -> 25482
A40: =A39+7 -> 45473 | B40: {=SUM('GPQ Scores'!B50:ACQ50)} -> 55431 | C40: 106 | D40: {=COUNTIF('GPQ Scores'!B50:JX50, ">1")} -> 2 | E40: {=AVERAGEIF('GPQ Scores'!B50:JX50, "<>0")} -> 27715.5
A41: =A40+7 -> 45480 | B41: {=SUM('GPQ Scores'!B51:ACQ51)} -> 52951 | C41: 109 | D41: {=COUNTIF('GPQ Scores'!B51:JX51, ">1")} -> 2 | E41: {=AVERAGEIF('GPQ Scores'!B51:JX51, "<>0")} -> 26475.5
A42: =A41+7 -> 45487 | B42: {=SUM('GPQ Scores'!B52:ACQ52)} -> 58194 | D42: {=COUNTIF('GPQ Scores'!B52:JX52, ">1")} -> 2 | E42: {=AVERAGEIF('GPQ Scores'!B52:JX52, "<>0")} -> 29097
A43: =A42+7 -> 45494 | B43: {=SUM('GPQ Scores'!B53:ACQ53)} -> 61905 | C43: 116 | D43: {=COUNTIF('GPQ Scores'!B53:JX53, ">1")} -> 2 | E43: {=AVERAGEIF('GPQ Scores'!B53:JX53, "<>0")} -> 30952.5
A44: =A43+7 -> 45501 | B44: {=SUM('GPQ Scores'!B54:ACQ54)} -> 63849 | D44: {=COUNTIF('GPQ Scores'!B54:JX54, ">1")} -> 2 | E44: {=AVERAGEIF('GPQ Scores'!B54:JX54, "<>0")} -> 31924.5
A45: =A44+7 -> 45508
A46: =A45+7 -> 45515
